<?xml version="1.0" encoding="utf-8"?>
<!-- This URDF was automatically created by SolidWorks to URDF Exporter! Originally created by Stephen Brawner (brawner@gmail.com) 
     Commit Version: 1.6.0-4-g7f85cfe  Build Version: 1.6.7995.38578
     For more information, please see http://wiki.ros.org/sw_urdf_exporter -->
<robot
  name="Assem_done_final_v2">
  <link
    name="base_link">
    <inertial>
      <origin
        xyz="-0.00062518 9.7341E-10 0.025048"
        rpy="0 0 0" />
      <mass
        value="1" />
      <inertia
        ixx="0.0003667"
        ixy="-2.025E-11"
        ixz="-8.5136E-07"
        iyy="0.00035887"
        iyz="-2.0693E-11"
        izz="0.00058409" />
    </inertial>
    <visual>
      <origin
        xyz="0 0 0"
        rpy="0 0 0" />
      <geometry>
        <mesh
          filename="package://Assem_done_final_v2/meshes/base_link.STL" />
      </geometry>
      <material
        name="">
        <color
          rgba="0.79216 0.81961 0.93333 1" />
      </material>
    </visual>
    <collision>
      <origin
        xyz="0 0 0"
        rpy="0 0 0" />
      <geometry>
        <mesh
          filename="package://Assem_done_final_v2/meshes/base_link.STL" />
      </geometry>
    </collision>
  </link>
  <link
    name="mid">
    <inertial>
      <origin
        xyz="-2.1139E-05 -0.0020926 0.11013"
        rpy="0 0 0" />
      <mass
        value="1.7" />
      <inertia
        ixx="0.00015003"
        ixy="-1.8933E-08"
        ixz="3.3207E-08"
        iyy="0.00016023"
        iyz="5.9883E-06"
        izz="0.00010422" />
    </inertial>
    <visual>
      <origin
        xyz="0 0 0"
        rpy="0 0 0" />
      <geometry>
        <mesh
          filename="package://Assem_done_final_v2/meshes/mid.STL" />
      </geometry>
      <material
        name="">
        <color
          rgba="0.79216 0.81961 0.93333 1" />
      </material>
    </visual>
    <collision>
      <origin
        xyz="0 0 0"
        rpy="0 0 0" />
      <geometry>
        <mesh
          filename="package://Assem_done_final_v2/meshes/mid.STL" />
      </geometry>
    </collision>
  </link>
  <joint
    name="joint1"
    type="revolute">
    <origin
      xyz="0 0 0"
      rpy="0 0 0" />
    <parent
      link="base_link" />
    <child
      link="mid" />
    <axis
      xyz="0 0 1" />
    <limit
      lower="0"
      upper="6.2832"
      effort="10"
      velocity="4" />
  </joint>
  <link
    name="link">
    <inertial>
      <origin
        xyz="0.04 -3.913E-07 0.027667"
        rpy="0 0 0" />
      <mass
        value="0.18" />
      <inertia
        ixx="1.2949E-05"
        ixy="-4.1233E-10"
        ixz="-4.0961E-11"
        iyy="9.3009E-05"
        iyz="8.4748E-11"
        izz="9.9834E-05" />
    </inertial>
    <visual>
      <origin
        xyz="0 0 0"
        rpy="0 0 0" />
      <geometry>
        <mesh
          filename="package://Assem_done_final_v2/meshes/link.STL" />
      </geometry>
      <material
        name="">
        <color
          rgba="0.79216 0.81961 0.93333 1" />
      </material>
    </visual>
    <collision>
      <origin
        xyz="0 0 0"
        rpy="0 0 0" />
      <geometry>
        <mesh
          filename="package://Assem_done_final_v2/meshes/link.STL" />
      </geometry>
    </collision>
  </link>
  <joint
    name="joint2"
    type="revolute">
    <origin
      xyz="-3E-05 0.0156 0.11817"
      rpy="-1.5708 0 0" />
    <parent
      link="mid" />
    <child
      link="link" />
    <axis
      xyz="0 0 1" />
    <limit
      lower="0.5236"
      upper="3.6652"
      effort="10"
      velocity="4" />
  </joint>
  <link
    name="end">
    <inertial>
      <origin
        xyz="0 -3.9708E-06 -0.025639"
        rpy="0 0 0" />
      <mass
        value="0.7" />
      <inertia
        ixx="3.1449E-05"
        ixy="2.2359E-20"
        ixz="2.7399E-20"
        iyy="3.1442E-05"
        iyz="8.759E-09"
        izz="2.7083E-05" />
    </inertial>
    <visual>
      <origin
        xyz="0 0 0"
        rpy="0 0 0" />
      <geometry>
        <mesh
          filename="package://Assem_done_final_v2/meshes/end.STL" />
      </geometry>
      <material
        name="">
        <color
          rgba="0.79216 0.81961 0.93333 1" />
      </material>
    </visual>
    <collision>
      <origin
        xyz="0 0 0"
        rpy="0 0 0" />
      <geometry>
        <mesh
          filename="package://Assem_done_final_v2/meshes/end.STL" />
      </geometry>
    </collision>
  </link>
  <joint
    name="joint3"
    type="revolute">
    <origin
      xyz="0.08 0 -0.0026"
      rpy="0 0 0" />
    <parent
      link="link" />
    <child
      link="end" />
    <axis
      xyz="0 0 1" />
    <limit
      lower="0"
      upper="6.2832"
      effort="10"
      velocity="4" />
  </joint>
</robot>